[2024-03-05T21:13:44.067+0000] {taskinstance.py:1956} INFO - Dependencies all met for dep_context=non-requeueable deps ti=<TaskInstance: citibikedataset.download_dataset scheduled__2022-12-01T00:00:00+00:00 [queued]>
[2024-03-05T21:13:44.071+0000] {taskinstance.py:1956} INFO - Dependencies all met for dep_context=requeueable deps ti=<TaskInstance: citibikedataset.download_dataset scheduled__2022-12-01T00:00:00+00:00 [queued]>
[2024-03-05T21:13:44.072+0000] {taskinstance.py:2170} INFO - Starting attempt 3 of 4
[2024-03-05T21:13:44.078+0000] {taskinstance.py:2191} INFO - Executing <Task(BashOperator): download_dataset> on 2022-12-01 00:00:00+00:00
[2024-03-05T21:13:44.082+0000] {standard_task_runner.py:60} INFO - Started process 186 to run task
[2024-03-05T21:13:44.084+0000] {standard_task_runner.py:87} INFO - Running: ['***', 'tasks', 'run', 'citibikedataset', 'download_dataset', 'scheduled__2022-12-01T00:00:00+00:00', '--job-id', '67', '--raw', '--subdir', 'DAGS_FOLDER/dag_citibikenyc.py', '--cfg-path', '/tmp/tmp3vuokqnx']
[2024-03-05T21:13:44.085+0000] {standard_task_runner.py:88} INFO - Job 67: Subtask download_dataset
[2024-03-05T21:13:44.109+0000] {task_command.py:423} INFO - Running <TaskInstance: citibikedataset.download_dataset scheduled__2022-12-01T00:00:00+00:00 [running]> on host 8277132cfd53
[2024-03-05T21:13:44.133+0000] {abstractoperator.py:707} ERROR - Exception rendering Jinja template for task 'download_dataset', field 'bash_command'. Template: "sh ${AIRFLOW_HOME}/include/download_bike_dataset.sh {{ ds.strftime('%Y') }} {{ ds.strftime('%m') }}"
Traceback (most recent call last):
  File "/home/airflow/.local/lib/python3.8/site-packages/airflow/models/abstractoperator.py", line 699, in _do_render_template_fields
    rendered_content = self.render_template(
  File "/home/airflow/.local/lib/python3.8/site-packages/airflow/template/templater.py", line 174, in render_template
    return self._render(template, context)
  File "/home/airflow/.local/lib/python3.8/site-packages/airflow/models/abstractoperator.py", line 654, in _render
    return super()._render(template, context, dag=dag)
  File "/home/airflow/.local/lib/python3.8/site-packages/airflow/template/templater.py", line 131, in _render
    return render_template_to_string(template, context)
  File "/home/airflow/.local/lib/python3.8/site-packages/airflow/utils/helpers.py", line 289, in render_template_to_string
    return render_template(template, cast(MutableMapping[str, Any], context), native=False)
  File "/home/airflow/.local/lib/python3.8/site-packages/airflow/utils/helpers.py", line 284, in render_template
    return "".join(nodes)
  File "<template>", line 13, in root
  File "/home/airflow/.local/lib/python3.8/site-packages/jinja2/sandbox.py", line 391, in call
    if not __self.is_safe_callable(__obj):
  File "/home/airflow/.local/lib/python3.8/site-packages/jinja2/sandbox.py", line 275, in is_safe_callable
    getattr(obj, "unsafe_callable", False) or getattr(obj, "alters_data", False)
  File "/home/airflow/.local/lib/python3.8/site-packages/jinja2/runtime.py", line 859, in __getattr__
    return self._fail_with_undefined_error()
  File "/home/airflow/.local/lib/python3.8/site-packages/jinja2/runtime.py", line 852, in _fail_with_undefined_error
    raise self._undefined_exception(self._undefined_message)
jinja2.exceptions.UndefinedError: 'str object' has no attribute 'strftime'
[2024-03-05T21:13:44.134+0000] {taskinstance.py:2698} ERROR - Task failed with exception
Traceback (most recent call last):
  File "/home/airflow/.local/lib/python3.8/site-packages/airflow/models/taskinstance.py", line 2334, in _run_raw_task
    self._execute_task_with_callbacks(context, test_mode, session=session)
  File "/home/airflow/.local/lib/python3.8/site-packages/airflow/models/taskinstance.py", line 2465, in _execute_task_with_callbacks
    task_orig = self.render_templates(context=context)
  File "/home/airflow/.local/lib/python3.8/site-packages/airflow/models/taskinstance.py", line 2877, in render_templates
    original_task.render_template_fields(context)
  File "/home/airflow/.local/lib/python3.8/site-packages/airflow/models/baseoperator.py", line 1241, in render_template_fields
    self._do_render_template_fields(self, self.template_fields, context, jinja_env, set())
  File "/home/airflow/.local/lib/python3.8/site-packages/airflow/utils/session.py", line 79, in wrapper
    return func(*args, session=session, **kwargs)
  File "/home/airflow/.local/lib/python3.8/site-packages/airflow/models/abstractoperator.py", line 699, in _do_render_template_fields
    rendered_content = self.render_template(
  File "/home/airflow/.local/lib/python3.8/site-packages/airflow/template/templater.py", line 174, in render_template
    return self._render(template, context)
  File "/home/airflow/.local/lib/python3.8/site-packages/airflow/models/abstractoperator.py", line 654, in _render
    return super()._render(template, context, dag=dag)
  File "/home/airflow/.local/lib/python3.8/site-packages/airflow/template/templater.py", line 131, in _render
    return render_template_to_string(template, context)
  File "/home/airflow/.local/lib/python3.8/site-packages/airflow/utils/helpers.py", line 289, in render_template_to_string
    return render_template(template, cast(MutableMapping[str, Any], context), native=False)
  File "/home/airflow/.local/lib/python3.8/site-packages/airflow/utils/helpers.py", line 284, in render_template
    return "".join(nodes)
  File "<template>", line 13, in root
  File "/home/airflow/.local/lib/python3.8/site-packages/jinja2/sandbox.py", line 391, in call
    if not __self.is_safe_callable(__obj):
  File "/home/airflow/.local/lib/python3.8/site-packages/jinja2/sandbox.py", line 275, in is_safe_callable
    getattr(obj, "unsafe_callable", False) or getattr(obj, "alters_data", False)
  File "/home/airflow/.local/lib/python3.8/site-packages/jinja2/runtime.py", line 859, in __getattr__
    return self._fail_with_undefined_error()
  File "/home/airflow/.local/lib/python3.8/site-packages/jinja2/runtime.py", line 852, in _fail_with_undefined_error
    raise self._undefined_exception(self._undefined_message)
jinja2.exceptions.UndefinedError: 'str object' has no attribute 'strftime'
[2024-03-05T21:13:44.137+0000] {taskinstance.py:1138} INFO - Marking task as UP_FOR_RETRY. dag_id=citibikedataset, task_id=download_dataset, execution_date=20221201T000000, start_date=20240305T211344, end_date=20240305T211344
[2024-03-05T21:13:44.144+0000] {standard_task_runner.py:107} ERROR - Failed to execute job 67 for task download_dataset ('str object' has no attribute 'strftime'; 186)
[2024-03-05T21:13:44.175+0000] {local_task_job_runner.py:234} INFO - Task exited with return code 1
[2024-03-05T21:13:44.191+0000] {taskinstance.py:3280} INFO - 0 downstream tasks scheduled from follow-on schedule check
